<?xml version="1.0" ?>

<robot name="testbot">
    <link name="base">
        <visual>
            <geometry>
                <mesh filename="package://testbot_description/meshes/visual/link0.stl" />
            </geometry>
        </visual>
        <collision>
            <geometry>
                <mesh filename="package://testbot_description/meshes/collision/link0.stl" />
            </geometry>
        </collision>
    </link>
    <link name="link1">
        <visual>
            <geometry>
                <mesh filename="package://testbot_description/meshes/visual/link1.stl" />
            </geometry>
        </visual>
        <collision>
            <geometry>
                <mesh filename="package://testbot_description/meshes/collision/link1.stl" />
            </geometry>
        </collision>
    </link>
    <joint name="joint1" type="revolute">
        <origin rpy="1.57079632679 0 0" xyz="0 0 0.08" />
        <parent link="base" />
        <child link="link1" />
        <axis xyz="0 1 0" />
        <limit effort="87" lower="-2.9671" upper="2.9671" velocity="2.3925" />
    </joint>
    <link name="link2">
        <visual>
            <geometry>
                <mesh filename="package://testbot_description/meshes/visual/link2.stl" />
            </geometry>
        </visual>
        <collision>
            <geometry>
                <mesh filename="package://testbot_description/meshes/collision/link2.stl" />
            </geometry>
        </collision>
    </link>
    <joint name="joint2" type="revolute">
        <origin rpy="1.57079632679 0 1.57079632679" xyz="0 0.125 0.13" />
        <parent link="link1" />
        <child link="link2" />
        <axis xyz="0 1 0" />
        <limit effort="87" lower="0" upper="2.9671" velocity="2.3925" />
    </joint>
    <link name="link3">
        <visual>
            <geometry>
                <mesh filename="package://testbot_description/meshes/visual/link3.stl" />
            </geometry>
        </visual>
        <collision>
            <geometry>
                <mesh filename="package://testbot_description/meshes/collision/link3.stl" />
            </geometry>
        </collision>
    </link>
    <joint name="fixed1" type="fixed">
        <origin rpy="0 3.14159265359 0" xyz="0 0 0.845" />
        <parent link="link2" />
        <child link="link3" />
    </joint>
    <link name="link4">
        <visual>
            <geometry>
                <mesh filename="package://testbot_description/meshes/visual/link4.stl" />
            </geometry>
        </visual>
        <collision>
            <geometry>
                <mesh filename="package://testbot_description/meshes/collision/link4.stl" />
            </geometry>
        </collision>
    </link>
    <joint name="joint3" type="revolute">
        <origin rpy="0 0 3.14159265359" xyz="0 -0.125 0" />
        <parent link="link3" />
        <child link="link4" />
        <axis xyz="0 1 0" />
        <limit effort="87" lower="-1.8326" upper="1.8326" velocity="2.3925" />
    </joint>
    <link name="link5">
        <visual>
            <geometry>
                <mesh filename="package://testbot_description/meshes/visual/link5.stl" />
            </geometry>
        </visual>
        <collision>
            <geometry>
                <mesh filename="package://testbot_description/meshes/collision/link5.stl" />
            </geometry>
        </collision>
    </link>
    <joint name="fixed2" type="fixed">
        <origin rpy="-1.57079632679 0 0" xyz="0 0 -0.78" />
        <parent link="link4" />
        <child link="link5" />
    </joint>
    <link name="link6">
        <visual>
            <geometry>
                <mesh filename="package://testbot_description/meshes/visual/link6.stl" />
            </geometry>
        </visual>
        <collision>
            <geometry>
                <mesh filename="package://testbot_description/meshes/collision/link6.stl" />
            </geometry>
        </collision>
    </link>
    <joint name="joint4" type="revolute">
        <origin rpy="1.57079632679 3.14159265359 0" xyz="0 0 -0.257" />
        <parent link="link5" />
        <child link="link6" />
        <axis xyz="0 1 0" />
        <limit effort="12" lower="-1.8326" upper="1.8326" velocity="2.3925" />
    </joint>
    <link name="link7">
        <visual>
            <geometry>
                <mesh filename="package://testbot_description/meshes/visual/link7.stl" />
            </geometry>
        </visual>
        <collision>
            <geometry>
                <mesh filename="package://testbot_description/meshes/collision/link7.stl" />
            </geometry>
        </collision>
    </link>
    <joint name="joint5" type="revolute">
        <origin rpy="-1.57079632679 0 0" xyz="0 0 -0.2" />
        <parent link="link6" />
        <child link="link7" />
        <axis xyz="0 1 0" />
        <limit effort="12" lower="-1.8326" upper="1.8326" velocity="2.3925" />
    </joint>
    <link name="link8">
        <visual>
            <geometry>
                <mesh filename="package://testbot_description/meshes/visual/link8.stl" />
            </geometry>
        </visual>
        <collision>
            <geometry>
                <mesh filename="package://testbot_description/meshes/collision/link8.stl" />
            </geometry>
        </collision>
    </link>
    <joint name="joint6" type="revolute">
        <origin rpy="0 0 0" xyz="0 0 -0.2005" />
        <parent link="link7" />
        <child link="link8" />
        <axis xyz="0 0 1" />
        <limit effort="12" lower="-1.8326" upper="1.8326" velocity="2.3925" />
    </joint>
</robot>